Workbook

Sheet Cube Index
B2: 📊 Cube Model Index
B3: Generated from WIP 4 — Brook Executive Dashboard 2026
B5: Dimensions
B6: Sheet | C6: Description | D6: Rows | E6: Key Columns
B7: dim_date | C7: Daily calendar grain for 2024–2026. Supports week (Sun–Sat) and month rollups. | D7: 1096 | E7: date_id (DDMMYY), week_start_sunday, month_name, quarter
B8: dim_kpi | C8: KPI catalog with domain, owner, unit type, cumulative flag. | D8: 24 | E8: kpi_id, domain, kpi_name, owner, unit, store_segment
B9: dim_initiative | C9: Initiative dimension across Tier 1, Product & Eng, People & Culture. | D9: 34 | E9: initiative_id, domain, initiative_name, owner, current_status
B11: Fact Tables
B12: Sheet | C12: Description | D12: Rows | E12: Key Columns
B13: fact_kpi_weekly | C13: Core numeric fact table — one row per KPI × measure × week. | D13: 910 | E13: date_id, kpi_name, measure_class, forecast_type, value, value_numeric
B14: fact_initiative_event | C14: Milestone events — one row per initiative × week with text + score. | D14: 110 | E14: date_id, initiative_id, milestone_text, status_score, status_label
B15: cube_unified | C15: Denormalized flat table joining facts + dimensions via INDEX/MATCH. Pivot-ready. | D15: 910 | E15: All fact_kpi_weekly cols + month_name, quarter, week_num, week_label, unit, is_cumulative
B17: Reference
B18: Sheet | C18: Description | D18: Rows | E18: Key Columns
B19: ref_monthly_narrative | C19: Monthly Big Picture commentary (March–December 2026). | D19: 10 | E19: month, year, narrative_text
B20: WIP 4 | C20: Original source dashboard (preserved as-is). | D20: 109 | E20: —
B22: WIP 4 (Cube) | C22: Reproduction of WIP 4 layout, fully driven by INDEX/MATCH from fact_kpi_weekly. | D22: 67 | E22: Same layout as WIP 4 — all data cells are formulas referencing the cube
B23: Schema Notes
B24: Join Keys | C24: fact_kpi_weekly.date_id → dim_date.date_id | fact_kpi_weekly.kpi_name → dim_kpi.kpi_name
C25: fact_initiative_event.initiative_id → dim_initiative.initiative_id
B26: Measure Structure | C26: measure_class (Goal / Forecast / Actual) + forecast_type (Internal / Board / Projection / blank)
B27: Status Scoring | C27: 1.0 = Complete, 0.75 = Near Complete, 0.5 = In Progress, 0.25 = Early Stage, 0.0 = Planned
B28: date_id Format | C28: YYMMDD (e.g., 260301 = March 1, 2026). Week starts Sunday.

Sheet cube_unified
A1: date_id | B1: week_start | C1: domain | D1: kpi_name | E1: measure_class | F1: forecast_type | G1: store_segment | H1: owner | I1: value | J1: value_numeric | K1: month_name | L1: month_num | M1: quarter | N1: week_num | O1: week_label | P1: unit | Q1: is_cumulative
A2: =fact_kpi_weekly!A2 -> 260301 | B2: =fact_kpi_weekly!B2 -> 46082 | C2: =fact_kpi_weekly!C2 -> Contracted Lives | D2: =fact_kpi_weekly!D2 -> Pipeline Growth - 6X Patient Count | E2: =fact_kpi_weekly!E2 -> Goal | F2: =IF(fact_kpi_weekly!F2="","",fact_kpi_weekly!F2) | G2: =fact_kpi_weekly!G2 -> N/A | H2: =fact_kpi_weekly!H2 -> John | I2: =fact_kpi_weekly!I2 -> $12M | J2: =fact_kpi_weekly!J2 -> 12000000 | K2: {=IFERROR(INDEX(dim_date!H:H,MATCH(A2,dim_date!A:A,0)),"")} -> Mar | L2: {=IFERROR(INDEX(dim_date!G:G,MATCH(A2,dim_date!A:A,0)),"")} -> 03 | M2: {=IFERROR(INDEX(dim_date!I:I,MATCH(A2,dim_date!A:A,0)),"")} -> Q1 | N2: {=IFERROR(INDEX(dim_date!K:K,MATCH(A2,dim_date!A:A,0)),"")} -> 10 | O2: {=IFERROR(INDEX(dim_date!F:F,MATCH(A2,dim_date!A:A,0)),"")} -> 3/1-3/7 | P2: {=IFERROR(INDEX(dim_kpi!E:E,MATCH(D2,dim_kpi!C:C,0)),"")} -> $ | Q2: {=IFERROR(INDEX(dim_kpi!F:F,MATCH(D2,dim_kpi!C:C,0)),"")} -> N
A3: =fact_kpi_weekly!A3 -> 260308 | B3: =fact_kpi_weekly!B3 -> 46089 | C3: =fact_kpi_weekly!C3 -> Contracted Lives | D3: =fact_kpi_weekly!D3 -> Pipeline Growth - 6X Patient Count | E3: =fact_kpi_weekly!E3 -> Goal | F3: =IF(fact_kpi_weekly!F3="","",fact_kpi_weekly!F3) | G3: =fact_kpi_weekly!G3 -> N/A | H3: =fact_kpi_weekly!H3 -> John | I3: =fact_kpi_weekly!I3 -> $12M | J3: =fact_kpi_weekly!J3 -> 12000000 | K3: {=IFERROR(INDEX(dim_date!H:H,MATCH(A3,dim_date!A:A,0)),"")} -> Mar | L3: {=IFERROR(INDEX(dim_date!G:G,MATCH(A3,dim_date!A:A,0)),"")} -> 03 | M3: {=IFERROR(INDEX(dim_date!I:I,MATCH(A3,dim_date!A:A,0)),"")} -> Q1 | N3: {=IFERROR(INDEX(dim_date!K:K,MATCH(A3,dim_date!A:A,0)),"")} -> 11 | O3: {=IFERROR(INDEX(dim_date!F:F,MATCH(A3,dim_date!A:A,0)),"")} -> 3/8-3/14 | P3: {=IFERROR(INDEX(dim_kpi!E:E,MATCH(D3,dim_kpi!C:C,0)),"")} -> $ | Q3: {=IFERROR(INDEX(dim_kpi!F:F,MATCH(D3,dim_kpi!C:C,0)),"")} -> N
A4: =fact_kpi_weekly!A4 -> 260315 | B4: =fact_kpi_weekly!B4 -> 46096 | C4: =fact_kpi_weekly!C4 -> Contracted Lives | D4: =fact_kpi_weekly!D4 -> Pipeline Growth - 6X Patient Count | E4: =fact_kpi_weekly!E4 -> Goal | F4: =IF(fact_kpi_weekly!F4="","",fact_kpi_weekly!F4) | G4: =fact_kpi_weekly!G4 -> N/A | H4: =fact_kpi_weekly!H4 -> John | I4: =fact_kpi_weekly!I4 -> $12M | J4: =fact_kpi_weekly!J4 -> 12000000 | K4: {=IFERROR(INDEX(dim_date!H:H,MATCH(A4,dim_date!A:A,0)),"")} -> Mar | L4: {=IFERROR(INDEX(dim_date!G:G,MATCH(A4,dim_date!A:A,0)),"")} -> 03 | M4: {=IFERROR(INDEX(dim_date!I:I,MATCH(A4,dim_date!A:A,0)),"")} -> Q1 | N4: {=IFERROR(INDEX(dim_date!K:K,MATCH(A4,dim_date!A:A,0)),"")} -> 12 | O4: {=IFERROR(INDEX(dim_date!F:F,MATCH(A4,dim_date!A:A,0)),"")} -> 3/15-3/21 | P4: {=IFERROR(INDEX(dim_kpi!E:E,MATCH(D4,dim_kpi!C:C,0)),"")} -> $ | Q4: {=IFERROR(INDEX(dim_kpi!F:F,MATCH(D4,dim_kpi!C:C,0)),"")} -> N
A5: =fact_kpi_weekly!A5 -> 260322 | B5: =fact_kpi_weekly!B5 -> 46103 | C5: =fact_kpi_weekly!C5 -> Contracted Lives | D5: =fact_kpi_weekly!D5 -> Pipeline Growth - 6X Patient Count | E5: =fact_kpi_weekly!E5 -> Goal | F5: =IF(fact_kpi_weekly!F5="","",fact_kpi_weekly!F5) | G5: =fact_kpi_weekly!G5 -> N/A | H5: =fact_kpi_weekly!H5 -> John | I5: =fact_kpi_weekly!I5 -> $12M | J5: =fact_kpi_weekly!J5 -> 12000000 | K5: {=IFERROR(INDEX(dim_date!H:H,MATCH(A5,dim_date!A:A,0)),"")} -> Mar | L5: {=IFERROR(INDEX(dim_date!G:G,MATCH(A5,dim_date!A:A,0)),"")} -> 03 | M5: {=IFERROR(INDEX(dim_date!I:I,MATCH(A5,dim_date!A:A,0)),"")} -> Q1 | N5: {=IFERROR(INDEX(dim_date!K:K,MATCH(A5,dim_date!A:A,0)),"")} -> 13 | O5: {=IFERROR(INDEX(dim_date!F:F,MATCH(A5,dim_date!A:A,0)),"")} -> 3/22-3/28 | P5: {=IFERROR(INDEX(dim_kpi!E:E,MATCH(D5,dim_kpi!C:C,0)),"")} -> $ | Q5: {=IFERROR(INDEX(dim_kpi!F:F,MATCH(D5,dim_kpi!C:C,0)),"")} -> N
A6: =fact_kpi_weekly!A6 -> 260329 | B6: =fact_kpi_weekly!B6 -> 46110 | C6: =fact_kpi_weekly!C6 -> Contracted Lives | D6: =fact_kpi_weekly!D6 -> Pipeline Growth - 6X Patient Count | E6: =fact_kpi_weekly!E6 -> Goal | F6: =IF(fact_kpi_weekly!F6="","",fact_kpi_weekly!F6) | G6: =fact_kpi_weekly!G6 -> N/A | H6: =fact_kpi_weekly!H6 -> John | I6: =fact_kpi_weekly!I6 -> $12M | J6: =fact_kpi_weekly!J6 -> 12000000 | K6: {=IFERROR(INDEX(dim_date!H:H,MATCH(A6,dim_date!A:A,0)),"")} -> Mar | L6: {=IFERROR(INDEX(dim_date!G:G,MATCH(A6,dim_date!A:A,0)),"")} -> 03 | M6: {=IFERROR(INDEX(dim_date!I:I,MATCH(A6,dim_date!A:A,0)),"")} -> Q1 | N6: {=IFERROR(INDEX(dim_date!K:K,MATCH(A6,dim_date!A:A,0)),"")} -> 14 | O6: {=IFERROR(INDEX(dim_date!F:F,MATCH(A6,dim_date!A:A,0)),"")} -> 3/29-4/4 | P6: {=IFERROR(INDEX(dim_kpi!E:E,MATCH(D6,dim_kpi!C:C,0)),"")} -> $ | Q6: {=IFERROR(INDEX(dim_kpi!F:F,MATCH(D6,dim_kpi!C:C,0)),"")} -> N
A7: =fact_kpi_weekly!A7 -> 260405 | B7: =fact_kpi_weekly!B7 -> 46117 | C7: =fact_kpi_weekly!C7 -> Contracted Lives | D7: =fact_kpi_weekly!D7 -> Pipeline Growth - 6X Patient Count | E7: =fact_kpi_weekly!E7 -> Goal | F7: =IF(fact_kpi_weekly!F7="","",fact_kpi_weekly!F7) | G7: =fact_kpi_weekly!G7 -> N/A | H7: =fact_kpi_weekly!H7 -> John | I7: =fact_kpi_weekly!I7 -> $12M | J7: =fact_kpi_weekly!J7 -> 12000000 | K7: {=IFERROR(INDEX(dim_date!H:H,MATCH(A7,dim_date!A:A,0)),"")} -> Apr | L7: {=IFERROR(INDEX(dim_date!G:G,MATCH(A7,dim_date!A:A,0)),"")} -> 04 | M7: {=IFERROR(INDEX(dim_date!I:I,MATCH(A7,dim_date!A:A,0)),"")} -> Q2 | N7: {=IFERROR(INDEX(dim_date!K:K,MATCH(A7,dim_date!A:A,0)),"")} -> 15 | O7: {=IFERROR(INDEX(dim_date!F:F,MATCH(A7,dim_date!A:A,0)),"")} -> 4/5-4/11 | P7: {=IFERROR(INDEX(dim_kpi!E:E,MATCH(D7,dim_kpi!C:C,0)),"")} -> $ | Q7: {=IFERROR(INDEX(dim_kpi!F:F,MATCH(D7,dim_kpi!C:C,0)),"")} -> N
A8: =fact_kpi_weekly!A8 -> 260412 | B8: =fact_kpi_weekly!B8 -> 46124 | C8: =fact_kpi_weekly!C8 -> Contracted Lives | D8: =fact_kpi_weekly!D8 -> Pipeline Growth - 6X Patient Count | E8: =fact_kpi_weekly!E8 -> Goal | F8: =IF(fact_kpi_weekly!F8="","",fact_kpi_weekly!F8) | G8: =fact_kpi_weekly!G8 -> N/A | H8: =fact_kpi_weekly!H8 -> John | I8: =fact_kpi_weekly!I8 -> $12M | J8: =fact_kpi_weekly!J8 -> 12000000 | K8: {=IFERROR(INDEX(dim_date!H:H,MATCH(A8,dim_date!A:A,0)),"")} -> Apr | L8: {=IFERROR(INDEX(dim_date!G:G,MATCH(A8,dim_date!A:A,0)),"")} -> 04 | M8: {=IFERROR(INDEX(dim_date!I:I,MATCH(A8,dim_date!A:A,0)),"")} -> Q2 | N8: {=IFERROR(INDEX(dim_date!K:K,MATCH(A8,dim_date!A:A,0)),"")} -> 16 | O8: {=IFERROR(INDEX(dim_date!F:F,MATCH(A8,dim_date!A:A,0)),"")} -> 4/12-4/18 | P8: {=IFERROR(INDEX(dim_kpi!E:E,MATCH(D8,dim_kpi!C:C,0)),"")} -> $ | Q8: {=IFERROR(INDEX(dim_kpi!F:F,MATCH(D8,dim_kpi!C:C,0)),"")} -> N
A9: =fact_kpi_weekly!A9 -> 260419 | B9: =fact_kpi_weekly!B9 -> 46131 | C9: =fact_kpi_weekly!C9 -> Contracted Lives | D9: =fact_kpi_weekly!D9 -> Pipeline Growth - 6X Patient Count | E9: =fact_kpi_weekly!E9 -> Goal | F9: =IF(fact_kpi_weekly!F9="","",fact_kpi_weekly!F9) | G9: =fact_kpi_weekly!G9 -> N/A | H9: =fact_kpi_weekly!H9 -> John | I9: =fact_kpi_weekly!I9 -> $12M | J9: =fact_kpi_weekly!J9 -> 12000000 | K9: {=IFERROR(INDEX(dim_date!H:H,MATCH(A9,dim_date!A:A,0)),"")} -> Apr | L9: {=IFERROR(INDEX(dim_date!G:G,MATCH(A9,dim_date!A:A,0)),"")} -> 04 | M9: {=IFERROR(INDEX(dim_date!I:I,MATCH(A9,dim_date!A:A,0)),"")} -> Q2 | N9: {=IFERROR(INDEX(dim_date!K:K,MATCH(A9,dim_date!A:A,0)),"")} -> 17 | O9: {=IFERROR(INDEX(dim_date!F:F,MATCH(A9,dim_date!A:A,0)),"")} -> 4/19-4/25 | P9: {=IFERROR(INDEX(dim_kpi!E:E,MATCH(D9,dim_kpi!C:C,0)),"")} -> $ | Q9: {=IFERROR(INDEX(dim_kpi!F:F,MATCH(D9,dim_kpi!C:C,0)),"")} -> N
A10: =fact_kpi_weekly!A10 -> 260426 | B10: =fact_kpi_weekly!B10 -> 46138 | C10: =fact_kpi_weekly!C10 -> Contracted Lives | D10: =fact_kpi_weekly!D10 -> Pipeline Growth - 6X Patient Count | E10: =fact_kpi_weekly!E10 -> Goal | F10: =IF(fact_kpi_weekly!F10="","",fact_kpi_weekly!F10) | G10: =fact_kpi_weekly!G10 -> N/A | H10: =fact_kpi_weekly!H10 -> John | I10: =fact_kpi_weekly!I10 -> $12M | J10: =fact_kpi_weekly!J10 -> 12000000 | K10: {=IFERROR(INDEX(dim_date!H:H,MATCH(A10,dim_date!A:A,0)),"")} -> Apr | L10: {=IFERROR(INDEX(dim_date!G:G,MATCH(A10,dim_date!A:A,0)),"")} -> 04 | M10: {=IFERROR(INDEX(dim_date!I:I,MATCH(A10,dim_date!A:A,0)),"")} -> Q2 | N10: {=IFERROR(INDEX(dim_date!K:K,MATCH(A10,dim_date!A:A,0)),"")} -> 18 | O10: {=IFERROR(INDEX(dim_date!F:F,MATCH(A10,dim_date!A:A,0)),"")} -> 4/26-5/2 | P10: {=IFERROR(INDEX(dim_kpi!E:E,MATCH(D10,dim_kpi!C:C,0)),"")} -> $ | Q10: {=IFERROR(INDEX(dim_kpi!F:F,MATCH(D10,dim_kpi!C:C,0)),"")} -> N
A11: =fact_kpi_weekly!A11 -> 260503 | B11: =fact_kpi_weekly!B11 -> 46145 | C11: =fact_kpi_weekly!C11 -> Contracted Lives | D11: =fact_kpi_weekly!D11 -> Pipeline Growth - 6X Patient Count | E11: =fact_kpi_weekly!E11 -> Goal | F11: =IF(fact_kpi_weekly!F11="","",fact_kpi_weekly!F11) | G11: =fact_kpi_weekly!G11 -> N/A | H11: =fact_kpi_weekly!H11 -> John | I11: =fact_kpi_weekly!I11 -> $13M | J11: =fact_kpi_weekly!J11 -> 13000000 | K11: {=IFERROR(INDEX(dim_date!H:H,MATCH(A11,dim_date!A:A,0)),"")} -> May | L11: {=IFERROR(INDEX(dim_date!G:G,MATCH(A11,dim_date!A:A,0)),"")} -> 05 | M11: {=IFERROR(INDEX(dim_date!I:I,MATCH(A11,dim_date!A:A,0)),"")} -> Q2 | N11: {=IFERROR(INDEX(dim_date!K:K,MATCH(A11,dim_date!A:A,0)),"")} -> 19 | O11: {=IFERROR(INDEX(dim_date!F:F,MATCH(A11,dim_date!A:A,0)),"")} -> 5/3-5/9 | P11: {=IFERROR(INDEX(dim_kpi!E:E,MATCH(D11,dim_kpi!C:C,0)),"")} -> $ | Q11: {=IFERROR(INDEX(dim_kpi!F:F,MATCH(D11,dim_kpi!C:C,0)),"")} -> N
A12: =fact_kpi_weekly!A12 -> 260510 | B12: =fact_kpi_weekly!B12 -> 46152 | C12: =fact_kpi_weekly!C12 -> Contracted Lives | D12: =fact_kpi_weekly!D12 -> Pipeline Growth - 6X Patient Count | E12: =fact_kpi_weekly!E12 -> Goal | F12: =IF(fact_kpi_weekly!F12="","",fact_kpi_weekly!F12) | G12: =fact_kpi_weekly!G12 -> N/A | H12: =fact_kpi_weekly!H12 -> John | I12: =fact_kpi_weekly!I12 -> $13M | J12: =fact_kpi_weekly!J12 -> 13000000 | K12: {=IFERROR(INDEX(dim_date!H:H,MATCH(A12,dim_date!A:A,0)),"")} -> May | L12: {=IFERROR(INDEX(dim_date!G:G,MATCH(A12,dim_date!A:A,0)),"")} -> 05 | M12: {=IFERROR(INDEX(dim_date!I:I,MATCH(A12,dim_date!A:A,0)),"")} -> Q2 | N12: {=IFERROR(INDEX(dim_date!K:K,MATCH(A12,dim_date!A:A,0)),"")} -> 20 | O12: {=IFERROR(INDEX(dim_date!F:F,MATCH(A12,dim_date!A:A,0)),"")} -> 5/10-5/16 | P12: {=IFERROR(INDEX(dim_kpi!E:E,MATCH(D12,dim_kpi!C:C,0)),"")} -> $ | Q12: {=IFERROR(INDEX(dim_kpi!F:F,MATCH(D12,dim_kpi!C:C,0)),"")} -> N
A13: =fact_kpi_weekly!A13 -> 260517 | B13: =fact_kpi_weekly!B13 -> 46159 | C13: =fact_kpi_weekly!C13 -> Contracted Lives | D13: =fact_kpi_weekly!D13 -> Pipeline Growth - 6X Patient Count | E13: =fact_kpi_weekly!E13 -> Goal | F13: =IF(fact_kpi_weekly!F13="","",fact_kpi_weekly!F13) | G13: =fact_kpi_weekly!G13 -> N/A | H13: =fact_kpi_weekly!H13 -> John | I13: =fact_kpi_weekly!I13 -> $13M | J13: =fact_kpi_weekly!J13 -> 13000000 | K13: {=IFERROR(INDEX(dim_date!H:H,MATCH(A13,dim_date!A:A,0)),"")} -> May | L13: {=IFERROR(INDEX(dim_date!G:G,MATCH(A13,dim_date!A:A,0)),"")} -> 05 | M13: {=IFERROR(INDEX(dim_date!I:I,MATCH(A13,dim_date!A:A,0)),"")} -> Q2 | N13: {=IFERROR(INDEX(dim_date!K:K,MATCH(A13,dim_date!A:A,0)),"")} -> 21 | O13: {=IFERROR(INDEX(dim_date!F:F,MATCH(A13,dim_date!A:A,0)),"")} -> 5/17-5/23 | P13: {=IFERROR(INDEX(dim_kpi!E:E,MATCH(D13,dim_kpi!C:C,0)),"")} -> $ | Q13: {=IFERROR(INDEX(dim_kpi!F:F,MATCH(D13,dim_kpi!C:C,0)),"")} -> N
... A911: =fact_kpi_weekly!A911 -> 260517 | B911: =fact_kpi_weekly!B911 -> 46159 | C911: =fact_kpi_weekly!C911 -> Care Delivery | D911: =fact_kpi_weekly!D911 -> Optimization of Care Delivery Time to Billed | E911: =fact_kpi_weekly!E911 -> Actual | F911: =IF(fact_kpi_weekly!F911="","",fact_kpi_weekly!F911) | G911: =fact_kpi_weekly!G911 -> N/A | H911: =fact_kpi_weekly!H911 -> Alex & Kit | I911: =fact_kpi_weekly!I911 -> 0.86 | J911: =fact_kpi_weekly!J911 -> 0.86 | K911: {=IFERROR(INDEX(dim_date!H:H,MATCH(A911,dim_date!A:A,0)),"")} -> May | L911: {=IFERROR(INDEX(dim_date!G:G,MATCH(A911,dim_date!A:A,0)),"")} -> 05 | M911: {=IFERROR(INDEX(dim_date!I:I,MATCH(A911,dim_date!A:A,0)),"")} -> Q2 | N911: {=IFERROR(INDEX(dim_date!K:K,MATCH(A911,dim_date!A:A,0)),"")} -> 21 | O911: {=IFERROR(INDEX(dim_date!F:F,MATCH(A911,dim_date!A:A,0)),"")} -> 5/17-5/23 | P911: {=IFERROR(INDEX(dim_kpi!E:E,MATCH(D911,dim_kpi!C:C,0)),"")} -> % | Q911: {=IFERROR(INDEX(dim_kpi!F:F,MATCH(D911,dim_kpi!C:C,0)),"")} -> N

Sheet dim_date
A1: date_id | B1: date | C1: day_of_week | D1: week_start_sunday | E1: week_end_saturday | F1: week_label | G1: month_num | H1: month_name | I1: quarter | J1: year | K1: week_num | M1: ← Back to Cube Index
A2: 240101 | B2: 45292 | C2: Mon | D2: 45291 | E2: 45297 | F2: 12/31-1/6 | G2: 01 | H2: Jan | I2: Q1 | J2: 2024 | K2: 01
A3: 240102 | B3: 45293 | C3: Tue | D3: 45291 | E3: 45297 | F3: 12/31-1/6 | G3: 01 | H3: Jan | I3: Q1 | J3: 2024 | K3: 01
A4: 240103 | B4: 45294 | C4: Wed | D4: 45291 | E4: 45297 | F4: 12/31-1/6 | G4: 01 | H4: Jan | I4: Q1 | J4: 2024 | K4: 01
A5: 240104 | B5: 45295 | C5: Thu | D5: 45291 | E5: 45297 | F5: 12/31-1/6 | G5: 01 | H5: Jan | I5: Q1 | J5: 2024 | K5: 01
A6: 240105 | B6: 45296 | C6: Fri | D6: 45291 | E6: 45297 | F6: 12/31-1/6 | G6: 01 | H6: Jan | I6: Q1 | J6: 2024 | K6: 01
A7: 240106 | B7: 45297 | C7: Sat | D7: 45291 | E7: 45297 | F7: 12/31-1/6 | G7: 01 | H7: Jan | I7: Q1 | J7: 2024 | K7: 01
A8: 240107 | B8: 45298 | C8: Sun | D8: 45298 | E8: 45304 | F8: 1/7-1/13 | G8: 01 | H8: Jan | I8: Q1 | J8: 2024 | K8: 02
A9: 240108 | B9: 45299 | C9: Mon | D9: 45298 | E9: 45304 | F9: 1/7-1/13 | G9: 01 | H9: Jan | I9: Q1 | J9: 2024 | K9: 02
A10: 240109 | B10: 45300 | C10: Tue | D10: 45298 | E10: 45304 | F10: 1/7-1/13 | G10: 01 | H10: Jan | I10: Q1 | J10: 2024 | K10: 02
A11: 240110 | B11: 45301 | C11: Wed | D11: 45298 | E11: 45304 | F11: 1/7-1/13 | G11: 01 | H11: Jan | I11: Q1 | J11: 2024 | K11: 02
A12: 240111 | B12: 45302 | C12: Thu | D12: 45298 | E12: 45304 | F12: 1/7-1/13 | G12: 01 | H12: Jan | I12: Q1 | J12: 2024 | K12: 02
A13: 240112 | B13: 45303 | C13: Fri | D13: 45298 | E13: 45304 | F13: 1/7-1/13 | G13: 01 | H13: Jan | I13: Q1 | J13: 2024 | K13: 02
... A1097: 261231 | B1097: 46387 | C1097: Thu | D1097: 46383 | E1097: 46389 | F1097: 12/27-1/2 | G1097: 12 | H1097: Dec | I1097: Q4 | J1097: 2026 | K1097: 53

Sheet dim_kpi
A1: kpi_id | B1: domain | C1: kpi_name | D1: owner | E1: unit | F1: is_cumulative | G1: store_segment | H1: source_rows_wip4 | K1: ← Back to Cube Index
A2: KPI-01 | B2: Contracted Lives | C2: Pipeline Growth - 6X Patient Count | D2: John | E2: $ | F2: N | G2: N/A | H2: 15-16
A3: KPI-02 | B3: Contracted Lives | C3: Pipeline Growth - 6X Revenue | D3: John | E3: $ | F3: N | G3: N/A | H3: 17-18
A4: KPI-03 | B4: Contracted Lives | C4: Deals Completed | D4: John | E4: text | F4: N | G4: N/A | H4: 19-20
A5: KPI-04 | B5: Contracted Lives | C5: Implementations Completed | D5: John & Sheila | E5: text | F5: N | G5: N/A | H5: 21-00
A6: KPI-05 | B6: Contracted Lives | C6: Eligible Forecast - Total Cumulative | D6: John / Sheila | E6: count | F6: Y | G6: Total | H6: 22-23
A7: KPI-06 | B7: Contracted Lives | C7: Eligible Forecast - New Store Cumulative | D7: John / Sheila | E7: count | F7: Y | G7: New Store | H7: 24-25
A8: KPI-07 | B8: Contracted Lives | C8: Eligible Forecast - Same Store Cumulative | D8: John / Sheila | E8: count | F8: Y | G8: Same Store | H8: 26-27
A9: KPI-08 | B9: Growth | C9: Marketable Patients - Accumulated | D9: Sheila | E9: count | F9: Y | G9: N/A | H9: 29-30
A10: KPI-09 | B10: Growth | C10: New Marketable Patients - New Store | D10: John | E10: count | F10: N | G10: New Store | H10: 31-32
A11: KPI-10 | B11: Growth | C11: New Marketable Patients - Same Store | D11: Sheila | E11: count | F11: N | G11: Same Store | H11: 33-34
A12: KPI-11 | B12: Growth | C12: Conversion Rate | D12: Luke | E12: % | F12: N | G12: N/A | H12: 35-36
A13: KPI-12 | B13: Growth | C13: Total Activations | D13: Luke | E13: count | F13: N | G13: N/A | H13: 37-40
... A25: KPI-24 | B25: Care Delivery | C25: Optimization of Care Delivery Time to Billed | D25: Alex & Kit | E25: % | F25: N | G25: N/A | H25: 66-00

Sheet dim_initiative
A1: initiative_id | B1: domain | C1: initiative_name | D1: owner | E1: current_status | H1: ← Back to Cube Index
A2: TIE-01 | B2: Tier 1 Initiative | C2: RPM 2026 (new codes) | D2: Team
A3: TIE-02 | B3: Tier 1 Initiative | C3: APCM | D3: Team
A4: TIE-03 | B4: Tier 1 Initiative | C4: RPM/PCM/CCM Product and onboarding | D4: Team
A5: TIE-04 | B5: Tier 1 Initiative | C5: Griffin CCM transition and growth | D5: Sheila & Luke
A6: TIE-05 | B6: Tier 1 Initiative | C6: Brook+ acquisition | D6: Luke & Kit
A7: TIE-06 | B7: Tier 1 Initiative | C7: Care - Optimization -> Automation | D7: Alex & Kit
A8: TIE-07 | B8: Tier 1 Initiative | C8: Acquisition and Onboarding system | D8: Luke & Kit
A9: TIE-08 | B9: Tier 1 Initiative | C9: Patient retention | D9: Kit
A10: TIE-09 | B10: Tier 1 Initiative | C10: Med Management | D10: Team
A11: PRO-01 | B11: Product & Engineering | C11: RPM 2026 (new codes) | D11: Kit
A12: PRO-02 | B12: Product & Engineering | C12: APCM | D12: Kit & Alex
A13: PRO-03 | B13: Product & Engineering | C13: PCM/CCM | D13: Kit & Alex
... A29: PRO-19 | B29: Product & Engineering | C29: Patient satisfaction | D29: Kit
A30: PEO-01 | B30: People & Culture | C30: Avg time posted to offer - Leadership | D30: Tricia | E30: Less than 75 days
A31: PEO-02 | B31: People & Culture | C31: Avg time posted to offer - Technical | D31: Tricia | E31: Less than 60 days
A32: PEO-03 | B32: People & Culture | C32: Avg time posted to offer - IC | D32: Tricia | E32: Less than 45 days
A33: PEO-04 | B33: People & Culture | C33: Employee Regrettable Turnover | D33: Tricia | E33: Annualized under 15%
A34: PEO-05 | B34: People & Culture | C34: Employee Regrettable Turnover under 1 year | D34: Tricia | E34: Annualized under 10%
A35: PEO-06 | B35: People & Culture | C35: HR Calendar | D35: Tricia

Sheet fact_kpi_weekly
A1: date_id | B1: week_start | C1: domain | D1: kpi_name | E1: measure_class | F1: forecast_type | G1: store_segment | H1: owner | I1: value | J1: value_numeric | M1: ← Back to Cube Index
A2: 260301 | B2: 46082 | C2: Contracted Lives | D2: Pipeline Growth - 6X Patient Count | E2: Goal | G2: N/A | H2: John | I2: $12M | J2: 12000000
A3: 260308 | B3: 46089 | C3: Contracted Lives | D3: Pipeline Growth - 6X Patient Count | E3: Goal | G3: N/A | H3: John | I3: $12M | J3: 12000000
A4: 260315 | B4: 46096 | C4: Contracted Lives | D4: Pipeline Growth - 6X Patient Count | E4: Goal | G4: N/A | H4: John | I4: $12M | J4: 12000000
A5: 260322 | B5: 46103 | C5: Contracted Lives | D5: Pipeline Growth - 6X Patient Count | E5: Goal | G5: N/A | H5: John | I5: $12M | J5: 12000000
A6: 260329 | B6: 46110 | C6: Contracted Lives | D6: Pipeline Growth - 6X Patient Count | E6: Goal | G6: N/A | H6: John | I6: $12M | J6: 12000000
A7: 260405 | B7: 46117 | C7: Contracted Lives | D7: Pipeline Growth - 6X Patient Count | E7: Goal | G7: N/A | H7: John | I7: $12M | J7: 12000000
A8: 260412 | B8: 46124 | C8: Contracted Lives | D8: Pipeline Growth - 6X Patient Count | E8: Goal | G8: N/A | H8: John | I8: $12M | J8: 12000000
A9: 260419 | B9: 46131 | C9: Contracted Lives | D9: Pipeline Growth - 6X Patient Count | E9: Goal | G9: N/A | H9: John | I9: $12M | J9: 12000000
A10: 260426 | B10: 46138 | C10: Contracted Lives | D10: Pipeline Growth - 6X Patient Count | E10: Goal | G10: N/A | H10: John | I10: $12M | J10: 12000000
A11: 260503 | B11: 46145 | C11: Contracted Lives | D11: Pipeline Growth - 6X Patient Count | E11: Goal | G11: N/A | H11: John | I11: $13M | J11: 13000000
A12: 260510 | B12: 46152 | C12: Contracted Lives | D12: Pipeline Growth - 6X Patient Count | E12: Goal | G12: N/A | H12: John | I12: $13M | J12: 13000000
A13: 260517 | B13: 46159 | C13: Contracted Lives | D13: Pipeline Growth - 6X Patient Count | E13: Goal | G13: N/A | H13: John | I13: $13M | J13: 13000000
... A93: 260315 | B93: 46096 | C93: Contracted Lives | D93: Pipeline Growth - 6X Revenue | E93: Actual | G93: N/A | H93: John | I93: $115.2M | J93: 115200000
A94: 260301 | B94: 46082 | C94: Contracted Lives | D94: Eligible Forecast - Total Cumulative | E94: Forecast | G94: Total | H94: John / Sheila | I94: 10327 | J94: 10327
A95: 260308 | B95: 46089 | C95: Contracted Lives | D95: Eligible Forecast - Total Cumulative | E95: Forecast | G95: Total | H95: John / Sheila | I95: 11827 | J95: 11827
A96: 260315 | B96: 46096 | C96: Contracted Lives | D96: Eligible Forecast - Total Cumulative | E96: Forecast | G96: Total | H96: John / Sheila | I96: 13327 | J96: 13327
A97: 260322 | B97: 46103 | C97: Contracted Lives | D97: Eligible Forecast - Total Cumulative | E97: Forecast | G97: Total | H97: John / Sheila | I97: 14827 | J97: 14827
A98: 260329 | B98: 46110 | C98: Contracted Lives | D98: Eligible Forecast - Total Cumulative | E98: Forecast | G98: Total | H98: John / Sheila | I98: 19827 | J98: 19827
A99: 260405 | B99: 46117 | C99: Contracted Lives | D99: Eligible Forecast - Total Cumulative | E99: Forecast | G99: Total | H99: John / Sheila | I99: 21327 | J99: 21327
A100: 260412 | B100: 46124 | C100: Contracted Lives | D100: Eligible Forecast - Total Cumulative | E100: Forecast | G100: Total | H100: John / Sheila | I100: 22827 | J100: 22827
A101: 260419 | B101: 46131 | C101: Contracted Lives | D101: Eligible Forecast - Total Cumulative | E101: Forecast | G101: Total | H101: John / Sheila | I101: 24327 | J101: 24327
A102: 260426 | B102: 46138 | C102: Contracted Lives | D102: Eligible Forecast - Total Cumulative | E102: Forecast | G102: Total | H102: John / Sheila | I102: 40827 | J102: 40827
A103: 260503 | B103: 46145 | C103: Contracted Lives | D103: Eligible Forecast - Total Cumulative | E103: Forecast | G103: Total | H103: John / Sheila | I103: 42327 | J103: 42327
A104: 260510 | B104: 46152 | C104: Contracted Lives | D104: Eligible Forecast - Total Cumulative | E104: Forecast | G104: Total | H104: John / Sheila | I104: 43827 | J104: 43827
A105: 260517 | B105: 46159 | C105: Contracted Lives | D105: Eligible Forecast - Total Cumulative | E105: Forecast | G105: Total | H105: John / Sheila | I105: 50327 | J105: 50327
... A361: 260301 | B361: 46082 | C361: Growth | D361: New Marketable Patients - Same Store | E361: Actual | G361: Same Store | H361: Sheila | I361: 1500 | J361: 1500
A362: 260301 | B362: 46082 | C362: Growth | D362: Total Activations | E362: Forecast | F362: Internal | G362: N/A | H362: Luke | I362: 150 | J362: 150
A363: 260308 | B363: 46089 | C363: Growth | D363: Total Activations | E363: Forecast | F363: Internal | G363: N/A | H363: Luke | I363: 150 | J363: 150
A364: 260315 | B364: 46096 | C364: Growth | D364: Total Activations | E364: Forecast | F364: Internal | G364: N/A | H364: Luke | I364: 150 | J364: 150
A365: 260322 | B365: 46103 | C365: Growth | D365: Total Activations | E365: Forecast | F365: Internal | G365: N/A | H365: Luke | I365: 150 | J365: 150
A366: 260329 | B366: 46110 | C366: Growth | D366: Total Activations | E366: Forecast | F366: Internal | G366: N/A | H366: Luke | I366: 207 | J366: 207
A367: 260405 | B367: 46117 | C367: Growth | D367: Total Activations | E367: Forecast | F367: Internal | G367: N/A | H367: Luke | I367: 245 | J367: 245
A368: 260412 | B368: 46124 | C368: Growth | D368: Total Activations | E368: Forecast | F368: Internal | G368: N/A | H368: Luke | I368: 245 | J368: 245
A369: 260419 | B369: 46131 | C369: Growth | D369: Total Activations | E369: Forecast | F369: Internal | G369: N/A | H369: Luke | I369: 245 | J369: 245
A370: 260426 | B370: 46138 | C370: Growth | D370: Total Activations | E370: Forecast | F370: Internal | G370: N/A | H370: Luke | I370: 269 | J370: 269
A371: 260503 | B371: 46145 | C371: Growth | D371: Total Activations | E371: Forecast | F371: Internal | G371: N/A | H371: Luke | I371: 365 | J371: 365
A372: 260510 | B372: 46152 | C372: Growth | D372: Total Activations | E372: Forecast | F372: Internal | G372: N/A | H372: Luke | I372: 365 | J372: 365
A373: 260517 | B373: 46159 | C373: Growth | D373: Total Activations | E373: Forecast | F373: Internal | G373: N/A | H373: Luke | I373: 365 | J373: 365
... A493: 261227 | B493: 46383 | C493: Growth | D493: Total Activations | E493: Forecast | F493: Projection | G493: N/A | H493: Luke | I493: 244 | J493: 244
...

Sheet fact_initiative_event
A1: date_id | B1: week_start | C1: initiative_id | D1: initiative_name | E1: domain | F1: owner | G1: milestone_text | H1: status_score | I1: status_label | L1: ← Back to Cube Index
A2: 260301 | B2: 46082 | C2: TIE-02 | D2: APCM | E2: Tier 1 Initiative | F2: Team | G2: APCM capability on platform | H2: 0.25 | I2: Early Stage
A3: 260315 | B3: 46096 | C3: TIE-02 | D3: APCM | E3: Tier 1 Initiative | F3: Team | G3: Product training for Sales, PSM, billing (kit) | H3: 0.75 | I3: Near Complete
A4: 260322 | B4: 46103 | C4: TIE-02 | D4: APCM | E4: Tier 1 Initiative | F4: Team | G4: Delivery plan developed for Beney (Sheila) | H4: 0.5 | I4: In Progress
A5: 260412 | B5: 46124 | C5: TIE-02 | D5: APCM | E5: Tier 1 Initiative | F5: Team | G5: Patients identification, rollout plan, dry run-through (sheila, luke) | H5: 0.5 | I5: In Progress
A6: 260419 | B6: 46131 | C6: TIE-02 | D6: APCM | E6: Tier 1 Initiative | F6: Team | G6: First APCM patients on system (Sheila, Luke) | H6: 0.25 | I6: Early Stage
A7: 260426 | B7: 46138 | C7: TIE-02 | D7: APCM | E7: Tier 1 Initiative | F7: Team | G7: APCM Billing readiness. | H7: 0.75 | I7: Near Complete
A8: 260308 | B8: 46089 | C8: TIE-03 | D8: RPM/PCM/CCM Product and onboarding | E8: Tier 1 Initiative | F8: Team | G8: CCM onboarding v0.2 | H8: 0.75 | I8: Near Complete
A9: 260315 | B9: 46096 | C9: TIE-03 | D9: RPM/PCM/CCM Product and onboarding | E9: Tier 1 Initiative | F9: Team | G9: Prod update - 2 conditions | H9: 0.5 | I9: In Progress
A10: 260322 | B10: 46103 | C10: TIE-03 | D10: RPM/PCM/CCM Product and onboarding | E10: Tier 1 Initiative | F10: Team | G10: Change mgt plan for the Intake team (luke) | H10: 0.5 | I10: In Progress
A11: 260412 | B11: 46124 | C11: TIE-03 | D11: RPM/PCM/CCM Product and onboarding | E11: Tier 1 Initiative | F11: Team | G11: CCM onboarding v1.0 | H11: 0.75 | I11: Near Complete
A12: 260301 | B12: 46082 | C12: TIE-04 | D12: Griffin CCM transition and growth | E12: Tier 1 Initiative | F12: Sheila & Luke | G12: Warm transfers started | H12: 0.5 | I12: In Progress
A13: 260315 | B13: 46096 | C13: TIE-04 | D13: Griffin CCM transition and growth | E13: Tier 1 Initiative | F13: Sheila & Luke | G13: Letters sent to Engooden pts. (luke) | H13: 0.75 | I13: Near Complete
... A111: 261206 | B111: 46362 | C111: PEO-06 | D111: HR Calendar | E111: People & Culture | F111: Tricia | G111: Headcount & budget finalized | H111: 1 | I111: Complete

Sheet ref_monthly_narrative
A1: month | B1: year | C1: narrative_text | F1: ← Back to Cube Index
A2: March | B2: 2026 | C2: New activations - 653, total actives EO March - 8,584 1. CCM rollout - 20% of new activations (=130), Griffin as lead, Highgate second 2. RPM 2026 codes - accepted at all accounts (Oren / John / Sheila) 3. Care Efficiency - workforce management - impact (Alex / Kit / Gregg) 4. 3 new contracts need to be signed this month (John) and implementation starting. 5. Completed transition of Highgate from implementation to PSM 6. $0 Copay BI automation 7. CCM onboarding at Griffin + WNY: 100 activations 8. Highgate ramping: 100 activations
A3: April | B3: 2026 | C3: Activations = 1,088. Total actives = 9,348 1. APCM - launched with 1 clinics; X patients (define KPI? Kit/Kelsey) 2. Care Efficiency - impact 3. Brook+ registration conversion improvements - (target 85%) 4. CMN restarted - target if 400 new activation in '26 5. New HS launched - target of 1,500 new patients in '26 - mitigation decision by 3/24/26 6. Griffin CCM transition - goal is to have 850 (200 on RPM currently) Griffin CCM active by end of April. Plan readiness? 7. Comp planning (Gregg/Tricia) 8. 2026 Partner Kick Off 4/20-4/23 9. Engooden patient migration (600 activations) 10. Sturdy opening diagnosis partner rules
A4: May | B4: 2026 | C4: Activations = 1,463. Total actives = 10,462 1. new HS launched - target of 900 new patients in '26 2. new clinic launched - target of 300 new patients in '26 - Need signatures by 3/24/26 3. Patient Retention improvements (SMS nudges)- impact 4. Employee Performance reviews completed??? 5. 3 new partner wins 6. 685 activations forecast to come from new store in May 7. Open (or near open) access to qualified Sturdy patients
A5: June | B5: 2026 | C5: Activations = 1,713. Total actives = 11,784 1. two new clinics launched - target of 1,200 patients in '26 2. Med Mgmt 1st partner contract signed (dependent on revenue convo) 3. By end of June, debt line / financing devices 4. BI. as a service - impact
A6: July | B6: 2026 | C6: Activations = 2,038. Total actives = 13,381 1. Med Management launch, rollout to XX partners 2. new HS launched - target of 1,000 patients in '26 3. Med Mgmt 1st partner launched; Med Mgmt 2nd partner contract signed 4. BI moved to outside vendor 5. Board Retreat
A7: August | B7: 2026 | C7: Activations = 2,228. Total actives = 15,112 1. New clinic launch - target of 600 patients in '26 Med Mgmt 2nd partner launch
A8: September | B8: 2026 | C8: Activations = 2,518. Total actives = 17,074 1. New HS and new Clinic launched - target of 500 new patients in '26.
A9: October | B9: 2026 | C9: Activations = 2,713. Total actives = 19,170 1. new clinic and new HS launch - target of 400 new patients in '26 2.
A10: November | B10: 2026 | C10: Activations = 2,453. Total actives = 20,937 1. new clinic and new HS launch - targeting 150 new patients in '26
A11: December | B11: 2026 | C11: Activations = 2,197. Total actives = 22,407

Sheet enrollment - combined (New)
D2: Start Date | BK2: 46026 | BL2: 46033 | BM2: 46040 | BN2: 46047 | BO2: 46054 | BP2: 46061 | BQ2: 46068 | BR2: 46075 | BS2: 46082 | BT2: 46089 | BU2: 46096 | BV2: 46103 | BW2: 46110 | BX2: 46117 | BY2: 46124 | BZ2: 46131 | CA2: 46138 | CB2: 46145 | CC2: 46152 | CD2: 46159 | CE2: 46166 | CF2: 46173 | CG2: 46180 | CH2: 46187 | CI2: 46194 | CJ2: 46201 | CK2: 46208 | CL2: 46215 | CM2: 46222 | CN2: 46229 | CO2: 46236 | CP2: 46243 | CQ2: 46250 | CR2: 46260 | CS2: 46264 | CT2: 46271 | CU2: 46278 | CV2: 46285 | CW2: 46292 | CX2: 46299 | CY2: 46306 | CZ2: 46313 | DA2: 46320 | DB2: 46327 | DC2: 46334 | DD2: 46341 | DE2: 46348 | DF2: 46355 | DG2: 46362 | DH2: 46369 | DI2: 46376 | DJ2: 46383
BK3: Week 1 | BL3: Week 2 | BM3: Week 3 | BN3: Week 4 | BO3: Week 5 | BP3: Week 6 | BQ3: Week 7 | BR3: Week 8 | BS3: Week 9 | BT3: Week 10 | BU3: Week 11 | BV3: Week 12 | BW3: Week 13 | BX3: Week 14 | BY3: Week 15 | BZ3: Week 16 | CA3: Week 17 | CB3: Week 18 | CC3: Week 19 | CD3: Week 20 | CE3: Week 21 | CF3: Week 22 | CG3: Week 23 | CH3: Week 24 | CI3: Week 25 | CJ3: Week 26 | CK3: Week 27 | CL3: Week 28 | CM3: Week 29 | CN3: Week 30 | CO3: Week 31 | CP3: Week 32 | CQ3: Week 33 | CR3: Week 34 | CS3: Week 35 | CT3: Week 36 | CU3: Week 37 | CV3: Week 38 | CW3: Week 39 | CX3: Week 40 | CY3: Week 41 | CZ3: Week 42 | DA3: Week 43 | DB3: Week 44 | DC3: Week 45 | DD3: Week 46 | DE3: Week 47 | DF3: Week 48 | DG3: Week 49 | DH3: Week 50 | DI3: Week 51 | DJ3: Week 52 | DK3: Total | DL3: check
C5: New Qualfied (John) | BV5: 5000 | BW5: 5000 | BX5: 20000 | BZ5: 10000 | CB5: 20000 | CD5: 10000 | CE5: 5000 | CG5: 20000 | CI5: 5000 | CK5: 40000 | CM5: 5000 | CO5: 10000 | CQ5: 5000 | CS5: 10000 | CT5: 10000 | CV5: 5000 | CW5: 10000 | CY5: 10000 | CZ5: 10000 | DB5: 40000 | DD5: 5000 | DF5: 5000
C6: New Qualified Unlocked (Sheila) | BV6: 3000 | BW6: 2500 | BX6: 10000 | BY6: 5000 | BZ6: 7500 | CA6: 10000 | CB6: 10000 | CC6: 2500 | CD6: 10000 | CE6: 5000 | CF6: 5000 | CG6: 10000 | CH6: 5000 | CI6: 5000 | CJ6: 5000 | CK6: 40000 | CL6: 5000 | CM6: 5000 | CN6: 2500 | CO6: 10000 | CP6: 2500 | CQ6: 2500 | CR6: 5000 | CS6: 5000 | CT6: 1000 | CU6: 2000 | CV6: 5000 | CW6: 10000 | CX6: 2500 | CY6: 2500 | CZ6: 10000 | DA6: 2500 | DB6: 40000 | DC6: 5000 | DD6: 2500 | DE6: 2500 | DF6: 5000 | DG6: 5000 | DH6: 5000 | DI6: 2500 | DJ6: 2500
C7: Locked Qualified | BR7: 10500 | BS7: 21592 | BT7: =BS7+BT5-BT6 -> 21592 | BU7: =BT7+BU5-BU6 -> 21592 | BV7: =BU7+BV5-BV6 -> 23592 | BW7: =BV7+BW5-BW6 -> 26092 | BX7: =BW7+BX5-BX6 -> 36092 | BY7: =BX7+BY5-BY6 -> 31092 | BZ7: =BY7+BZ5-BZ6 -> 33592 | CA7: =BZ7+CA5-CA6 -> 23592 | ... DJ7: =DI7+DJ5-DJ6 -> 8092
C9: Unlock Rate | BR9: 0.4 | BS9: 0.4 | BT9: 0.4 | BU9: 0.4 | BV9: 0.4 | BW9: 0.4 | BX9: 0.4 | BY9: 0.4 | BZ9: 0.4 | CA9: 0.4 | CB9: 0.4 | CC9: 0.4 | CD9: 0.4 | CE9: 0.4 | CF9: 0.4 | CG9: 0.4 | CH9: 0.4 | CI9: 0.4 | CJ9: 0.4 | CK9: 0.4 | CL9: 0.4 | CM9: 0.4 | CN9: 0.4 | CO9: 0.4 | CP9: 0.4 | CQ9: 0.4 | CR9: 0.4 | CS9: 0.4 | CT9: 0.4 | CU9: 0.4 | CV9: 0.4 | CW9: 0.4 | CX9: 0.4 | CY9: 0.4 | CZ9: 0.4 | DA9: 0.4 | DB9: 0.4 | DC9: 0.4 | DD9: 0.4 | DE9: 0.4 | DF9: 0.4 | DG9: 0.4 | DH9: 0.4 | DI9: 0.4 | DJ9: 0.4
C10: Pre-BI Unlocked Eligible | BK10: 11000 | BL10: 11000 | BM10: 11000 | BN10: 11000 | BO10: 11000 | BP10: 11000 | BQ10: 11000 | BR10: 11000 | BS10: =ROUND(BR12+(BS6*BS9),0) -> 9500 | BT10: =ROUND(BS12+(BT6*BT9),0) -> 8000 | BU10: =ROUND(BT12+(BU6*BU9),0) -> 0 | BV10: =ROUND(BU12+(BV6*BV9),0) -> 1200 | BW10: =ROUND(BV12+(BW6*BW9),0) -> 1000 | BX10: =ROUND(BW12+(BX6*BX9),0) -> 4000 | BY10: =ROUND(BX12+(BY6*BY9),0) -> 2000 | BZ10: =ROUND(BY12+(BZ6*BZ9),0) -> 3000 | ... DJ10: =ROUND(DI12+(DJ6*DJ9),0) -> 1000
C11: BI Pace | BK11: 1500 | BL11: 1500 | BM11: 1500 | BN11: 1500 | BO11: 1500 | BP11: 1500 | BQ11: 1500 | BR11: 1500 | BS11: 1500 | BT11: =BT10 -> 8000 | BU11: =BU10 -> 0 | BV11: =BV10 -> 1200 | BW11: =BW10 -> 1000 | BX11: =BX10 -> 4000 | BY11: =BY10 -> 2000 | BZ11: =BZ10 -> 3000 | CA11: =CA10 -> 4000 | ... DJ11: =DJ10 -> 1000
C12: Unlocked Eligible Backlog | BK12: =BK10-BK11 -> 9500 | BL12: =BL10-BL11 -> 9500 | BM12: =BM10-BM11 -> 9500 | BN12: =BN10-BN11 -> 9500 | BO12: =BO10-BO11 -> 9500 | BP12: =BP10-BP11 -> 9500 | BQ12: =BQ10-BQ11 -> 9500 | BR12: =BR10-BR11 -> 9500 | ... DJ12: =DJ10-DJ11 -> 0
C14: Unlock Rate | D14: NEED MARKETABLE RATE OF 80% | BK14: 0.8 | BL14: 0.8 | BM14: 0.8 | BN14: 0.8 | BO14: 0.8 | BP14: 0.8 | BQ14: 0.8 | BR14: 0.8 | BS14: 0.8 | BT14: 0.8 | BU14: 0.8 | BV14: 0.8 | BW14: 0.8 | BX14: 0.8 | BY14: 0.8 | BZ14: 0.8 | CA14: 0.8 | CB14: 0.8 | CC14: 0.8 | CD14: 0.8 | CE14: 0.8 | CF14: 0.8 | CG14: 0.8 | CH14: 0.8 | CI14: 0.8 | CJ14: 0.8 | CK14: 0.8 | CL14: 0.8 | CM14: 0.8 | CN14: 0.8 | CO14: 0.8 | CP14: 0.8 | CQ14: 0.8 | CR14: 0.8 | CS14: 0.8 | CT14: 0.8 | CU14: 0.8 | CV14: 0.8 | CW14: 0.8 | CX14: 0.8 | CY14: 0.8 | CZ14: 0.8 | DA14: 0.8 | DB14: 0.8 | DC14: 0.8 | DD14: 0.8 | DE14: 0.8 | DF14: 0.8 | DG14: 0.8 | DH14: 0.8 | DI14: 0.8 | DJ14: 0.8
C15: New Marketable | BK15: =BK11*BK14 -> 1200 | BL15: =BL11*BL14 -> 1200 | BM15: =BM11*BM14 -> 1200 | BN15: =BN11*BN14 -> 1200 | BO15: =BO11*BO14 -> 1200 | BP15: =BP11*BP14 -> 1200 | BQ15: =BQ11*BQ14 -> 1200 | BR15: =BR11*BR14 -> 1200 | ... DJ15: =DJ11*DJ14 -> 800
C17: Out Of Pocket Band
C18: 0 | D18: 0.35 | BK18: =ROUND(BK$15*$D18,0) -> 420 | BL18: =ROUND(BL$15*$D18,0) -> 420 | BM18: =ROUND(BM$15*$D18,0) -> 420 | BN18: =ROUND(BN$15*$D18,0) -> 420 | BO18: =ROUND(BO$15*$D18,0) -> 420 | BP18: =ROUND(BP$15*$D18,0) -> 420 | BQ18: =ROUND(BQ$15*$D18,0) -> 420 | BR18: =ROUND(BR$15*$D18,0) -> 420 | ... DJ18: =ROUND(DJ$15*$D18,0) -> 280
C19: 1 – 19 | D19: 0.05 | BK19: =ROUND(BK$15*$D19,0) -> 60 | BL19: =ROUND(BL$15*$D19,0) -> 60 | BM19: =ROUND(BM$15*$D19,0) -> 60 | BN19: =ROUND(BN$15*$D19,0) -> 60 | BO19: =ROUND(BO$15*$D19,0) -> 60 | BP19: =ROUND(BP$15*$D19,0) -> 60 | BQ19: =ROUND(BQ$15*$D19,0) -> 60 | BR19: =ROUND(BR$15*$D19,0) -> 60 | ... DJ19: =ROUND(DJ$15*$D19,0) -> 40
C20: 20 – 29 | D20: 0.15 | BK20: =ROUND(BK$15*$D20,0) -> 180 | BL20: =ROUND(BL$15*$D20,0) -> 180 | BM20: =ROUND(BM$15*$D20,0) -> 180 | BN20: =ROUND(BN$15*$D20,0) -> 180 | BO20: =ROUND(BO$15*$D20,0) -> 180 | BP20: =ROUND(BP$15*$D20,0) -> 180 | BQ20: =ROUND(BQ$15*$D20,0) -> 180 | BR20: =ROUND(BR$15*$D20,0) -> 180 | ... DJ20: =ROUND(DJ$15*$D20,0) -> 120
C21: 30 – 39 | D21: 0.05 | BK21: =ROUND(BK$15*$D21,0) -> 60 | BL21: =ROUND(BL$15*$D21,0) -> 60 | BM21: =ROUND(BM$15*$D21,0) -> 60 | BN21: =ROUND(BN$15*$D21,0) -> 60 | BO21: =ROUND(BO$15*$D21,0) -> 60 | BP21: =ROUND(BP$15*$D21,0) -> 60 | BQ21: =ROUND(BQ$15*$D21,0) -> 60 | BR21: =ROUND(BR$15*$D21,0) -> 60 | ... DJ21: =ROUND(DJ$15*$D21,0) -> 40
C22: 40 – 49 | D22: 0.05 | BK22: =ROUND(BK$15*$D22,0) -> 60 | BL22: =ROUND(BL$15*$D22,0) -> 60 | BM22: =ROUND(BM$15*$D22,0) -> 60 | BN22: =ROUND(BN$15*$D22,0) -> 60 | BO22: =ROUND(BO$15*$D22,0) -> 60 | BP22: =ROUND(BP$15*$D22,0) -> 60 | BQ22: =ROUND(BQ$15*$D22,0) -> 60 | BR22: =ROUND(BR$15*$D22,0) -> 60 | ... DJ22: =ROUND(DJ$15*$D22,0) -> 40
C23: 50+ | D23: 0.15 | BK23: =ROUND(BK$15*$D23,0) -> 180 | BL23: =ROUND(BL$15*$D23,0) -> 180 | BM23: =ROUND(BM$15*$D23,0) -> 180 | BN23: =ROUND(BN$15*$D23,0) -> 180 | BO23: =ROUND(BO$15*$D23,0) -> 180 | BP23: =ROUND(BP$15*$D23,0) -> 180 | BQ23: =ROUND(BQ$15*$D23,0) -> 180 | BR23: =ROUND(BR$15*$D23,0) -> 180 | ... DJ23: =ROUND(DJ$15*$D23,0) -> 120
C24: Deductible Remaining | D24: 0.2 | BK24: =ROUND(BK$15*$D24,0) -> 240 | BL24: =ROUND(BL$15*$D24,0) -> 240 | BM24: =ROUND(BM$15*$D24,0) -> 240 | BN24: =ROUND(BN$15*$D24,0) -> 240 | BO24: =ROUND(BO$15*$D24,0) -> 240 | BP24: =ROUND(BP$15*$D24,0) -> 240 | BQ24: =ROUND(BQ$15*$D24,0) -> 240 | BR24: =ROUND(BR$15*$D24,0) -> 240 | ... DJ24: =ROUND(DJ$15*$D24,0) -> 160
C26: Conversion Rate
C27: 0 | D27: 0.35 | BK27: =ROUND(BK18*$D27,0) -> 147 | BL27: =ROUND(BL18*$D27,0) -> 147 | BM27: =ROUND(BM18*$D27,0) -> 147 | BN27: =ROUND(BN18*$D27,0) -> 147 | BO27: =ROUND(BO18*$D27,0) -> 147 | BP27: =ROUND(BP18*$D27,0) -> 147 | BQ27: =ROUND(BQ18*$D27,0) -> 147 | BR27: =ROUND(BR18*$D27,0) -> 147 | ... DJ27: =ROUND(DJ18*$D27,0) -> 98
C28: 1 – 19 | D28: 0.25 | BK28: =ROUND(BK19*$D28,0) -> 15 | BL28: =ROUND(BL19*$D28,0) -> 15 | BM28: =ROUND(BM19*$D28,0) -> 15 | BN28: =ROUND(BN19*$D28,0) -> 15 | BO28: =ROUND(BO19*$D28,0) -> 15 | BP28: =ROUND(BP19*$D28,0) -> 15 | BQ28: =ROUND(BQ19*$D28,0) -> 15 | BR28: =ROUND(BR19*$D28,0) -> 15 | ... DJ28: =ROUND(DJ19*$D28,0) -> 10
C29: 20 – 29 | D29: 0.15 | BK29: =ROUND(BK20*$D29,0) -> 27 | BL29: =ROUND(BL20*$D29,0) -> 27 | BM29: =ROUND(BM20*$D29,0) -> 27 | BN29: =ROUND(BN20*$D29,0) -> 27 | BO29: =ROUND(BO20*$D29,0) -> 27 | BP29: =ROUND(BP20*$D29,0) -> 27 | BQ29: =ROUND(BQ20*$D29,0) -> 27 | BR29: =ROUND(BR20*$D29,0) -> 27 | ... DJ29: =ROUND(DJ20*$D29,0) -> 18
C30: 30 – 39 | D30: 0.09 | BK30: =ROUND(BK21*$D30,0) -> 5 | BL30: =ROUND(BL21*$D30,0) -> 5 | BM30: =ROUND(BM21*$D30,0) -> 5 | BN30: =ROUND(BN21*$D30,0) -> 5 | BO30: =ROUND(BO21*$D30,0) -> 5 | BP30: =ROUND(BP21*$D30,0) -> 5 | BQ30: =ROUND(BQ21*$D30,0) -> 5 | BR30: =ROUND(BR21*$D30,0) -> 5 | ... DJ30: =ROUND(DJ21*$D30,0) -> 4
C31: 40 – 49 | D31: 0.07 | BK31: =ROUND(BK22*$D31,0) -> 4 | BL31: =ROUND(BL22*$D31,0) -> 4 | BM31: =ROUND(BM22*$D31,0) -> 4 | BN31: =ROUND(BN22*$D31,0) -> 4 | BO31: =ROUND(BO22*$D31,0) -> 4 | BP31: =ROUND(BP22*$D31,0) -> 4 | BQ31: =ROUND(BQ22*$D31,0) -> 4 | BR31: =ROUND(BR22*$D31,0) -> 4 | ... DJ31: =ROUND(DJ22*$D31,0) -> 3
C32: 50+ | D32: 0.05 | BK32: =ROUND(BK23*$D32,0) -> 9 | BL32: =ROUND(BL23*$D32,0) -> 9 | BM32: =ROUND(BM23*$D32,0) -> 9 | BN32: =ROUND(BN23*$D32,0) -> 9 | BO32: =ROUND(BO23*$D32,0) -> 9 | BP32: =ROUND(BP23*$D32,0) -> 9 | BQ32: =ROUND(BQ23*$D32,0) -> 9 | BR32: =ROUND(BR23*$D32,0) -> 9 | ... DJ32: =ROUND(DJ23*$D32,0) -> 6
C33: Deductible Remaining | D33: 0.05 | BK33: =ROUND(BK24*$D33,0) -> 12 | BL33: =ROUND(BL24*$D33,0) -> 12 | BM33: =ROUND(BM24*$D33,0) -> 12 | BN33: =ROUND(BN24*$D33,0) -> 12 | BO33: =ROUND(BO24*$D33,0) -> 12 | BP33: =ROUND(BP24*$D33,0) -> 12 | BQ33: =ROUND(BQ24*$D33,0) -> 12 | BR33: =ROUND(BR24*$D33,0) -> 12 | ... DJ33: =ROUND(DJ24*$D33,0) -> 8
C35: Conversion Pace
B36: Week | C36: 1 | D36: 0 | E36: 0.07 | F36: 0.07 | G36: 0.07 | H36: 0.07 | I36: 0.07 | J36: 0.07 | K36: 0.07 | L36: 0.07 | M36: 0.07 | N36: 0.03 | O36: 0.03 | P36: 0.03 | Q36: 0.03 | R36: 0.03 | S36: 0.03 | T36: 0.03 | U36: 0.02 | V36: 0.02 | W36: 0.02 | X36: 0.02 | Y36: 0.02 | Z36: 0.02 | AA36: 0.02 | AB36: 0.02 | BK36: =ROUND($BK27*E36,0) -> 10 | BL36: =ROUND($BK27*F36,0) -> 10 | BM36: =ROUND($BK27*G36,0) -> 10 | BN36: =ROUND($BK27*H36,0) -> 10 | BO36: =ROUND($BK27*I36,0) -> 10 | BP36: =ROUND($BK27*J36,0) -> 10 | BQ36: =ROUND($BK27*K36,0) -> 10 | BR36: =ROUND($BK27*L36,0) -> 10 | ... DJ36: =ROUND($BK27*BD36,0) -> 0
B37: Week | C37: 1 | D37: 1 – 19 | E37: 0.02 | F37: 0.02 | G37: 0.02 | H37: 0.02 | I37: 0.08 | J37: 0.08 | K37: 0.07 | L37: 0.07 | M37: 0.06 | N37: 0.06 | O37: 0.05 | P37: 0.05 | Q37: 0.05 | R37: 0.04 | S37: 0.04 | T37: 0.04 | U37: 0.04 | V37: 0.03 | W37: 0.03 | X37: 0.03 | Y37: 0.03 | Z37: 0.03 | AA37: 0.02 | AB37: 0.02 | BK37: =ROUND($BK28*E37,0) -> 0 | BL37: =ROUND($BK28*F37,0) -> 0 | BM37: =ROUND($BK28*G37,0) -> 0 | BN37: =ROUND($BK28*H37,0) -> 0 | BO37: =ROUND($BK28*I37,0) -> 1 | BP37: =ROUND($BK28*J37,0) -> 1 | BQ37: =ROUND($BK28*K37,0) -> 1 | BR37: =ROUND($BK28*L37,0) -> 1 | ... DJ37: =ROUND($BK28*BD37,0) -> 0
B38: Week | C38: 1 | D38: 20 – 29 | H38: 0.08 | I38: 0.08 | J38: 0.07 | K38: 0.07 | L38: 0.06 | M38: 0.06 | N38: 0.05 | O38: 0.05 | P38: 0.05 | Q38: 0.04 | R38: 0.04 | S38: 0.04 | T38: 0.04 | U38: 0.03 | V38: 0.03 | W38: 0.03 | X38: 0.03 | Y38: 0.03 | Z38: 0.02 | AA38: 0.02 | AB38: 0.03 | AC38: 0.03 | AD38: 0.02 | BK38: =ROUND($BK29*E38,0) -> 0 | BL38: =ROUND($BK29*F38,0) -> 0 | BM38: =ROUND($BK29*G38,0) -> 0 | BN38: =ROUND($BK29*H38,0) -> 2 | BO38: =ROUND($BK29*I38,0) -> 2 | BP38: =ROUND($BK29*J38,0) -> 2 | BQ38: =ROUND($BK29*K38,0) -> 2 | BR38: =ROUND($BK29*L38,0) -> 2 | ... DJ38: =ROUND($BK29*BD38,0) -> 0
B39: Week | C39: 1 | D39: 30 – 39 | J39: 0.08 | K39: 0.08 | L39: 0.07 | M39: 0.07 | N39: 0.06 | O39: 0.06 | P39: 0.05 | Q39: 0.05 | R39: 0.05 | S39: 0.04 | T39: 0.04 | U39: 0.04 | V39: 0.04 | W39: 0.03 | X39: 0.03 | Y39: 0.03 | Z39: 0.03 | AA39: 0.03 | AB39: 0.02 | AC39: 0.02 | AD39: 0.03 | BK39: =ROUND($BK30*E39,0) -> 0 | BL39: =ROUND($BK30*F39,0) -> 0 | BM39: =ROUND($BK30*G39,0) -> 0 | BN39: =ROUND($BK30*H39,0) -> 0 | BO39: =ROUND($BK30*I39,0) -> 0 | BP39: =ROUND($BK30*J39,0) -> 0 | BQ39: =ROUND($BK30*K39,0) -> 0 | BR39: =ROUND($BK30*L39,0) -> 0 | ... DJ39: =ROUND($BK30*BD39,0) -> 0
B40: Week | C40: 1 | D40: 40 – 49 | K40: 0.08 | L40: 0.08 | M40: 0.07 | N40: 0.07 | O40: 0.06 | P40: 0.06 | Q40: 0.05 | R40: 0.05 | S40: 0.05 | T40: 0.04 | U40: 0.04 | V40: 0.04 | W40: 0.04 | X40: 0.03 | Y40: 0.03 | Z40: 0.03 | AA40: 0.03 | AB40: 0.03 | AC40: 0.02 | AD40: 0.02 | BK40: =ROUND($BK31*E40,0) -> 0 | BL40: =ROUND($BK31*F40,0) -> 0 | BM40: =ROUND($BK31*G40,0) -> 0 | BN40: =ROUND($BK31*H40,0) -> 0 | BO40: =ROUND($BK31*I40,0) -> 0 | BP40: =ROUND($BK31*J40,0) -> 0 | BQ40: =ROUND($BK31*K40,0) -> 0 | BR40: =ROUND($BK31*L40,0) -> 0 | ... DJ40: =ROUND($BK31*BD40,0) -> 0
B41: Week | C41: 1 | D41: 50+ | L41: 0.08 | M41: 0.08 | N41: 0.07 | O41: 0.07 | P41: 0.06 | Q41: 0.06 | R41: 0.05 | S41: 0.05 | T41: 0.05 | U41: 0.04 | V41: 0.04 | W41: 0.04 | X41: 0.04 | Y41: 0.03 | Z41: 0.03 | AA41: 0.03 | AB41: 0.03 | AC41: 0.03 | AD41: 0.02 | BK41: =ROUND($BK32*E41,0) -> 0 | BL41: =ROUND($BK32*F41,0) -> 0 | BM41: =ROUND($BK32*G41,0) -> 0 | BN41: =ROUND($BK32*H41,0) -> 0 | BO41: =ROUND($BK32*I41,0) -> 0 | BP41: =ROUND($BK32*J41,0) -> 0 | BQ41: =ROUND($BK32*K41,0) -> 0 | BR41: =ROUND($BK32*L41,0) -> 1 | ... DJ41: =ROUND($BK32*BD41,0) -> 0
B42: Week | C42: 1 | D42: Deductible Remaining | N42: 0.08 | O42: 0.08 | P42: 0.07 | Q42: 0.07 | R42: 0.06 | S42: 0.06 | T42: 0.05 | U42: 0.05 | V42: 0.05 | W42: 0.04 | X42: 0.04 | Y42: 0.04 | Z42: 0.04 | AA42: 0.03 | AB42: 0.03 | AC42: 0.03 | AD42: 0.03 | BK42: =ROUND($BK33*E42,0) -> 0 | BL42: =ROUND($BK33*F42,0) -> 0 | BM42: =ROUND($BK33*G42,0) -> 0 | BN42: =ROUND($BK33*H42,0) -> 0 | BO42: =ROUND($BK33*I42,0) -> 0 | BP42: =ROUND($BK33*J42,0) -> 0 | BQ42: =ROUND($BK33*K42,0) -> 0 | BR42: =ROUND($BK33*L42,0) -> 0 | ... DJ42: =ROUND($BK33*BD42,0) -> 0
B43: Week | C43: 2 | D43: 0 | E43: 0.07 | F43: 0.07 | G43: 0.07 | H43: 0.07 | I43: 0.07 | J43: 0.07 | K43: 0.07 | L43: 0.07 | M43: 0.07 | N43: 0.03 | O43: 0.03 | P43: 0.03 | Q43: 0.03 | R43: 0.03 | S43: 0.03 | T43: 0.03 | U43: 0.02 | V43: 0.02 | W43: 0.02 | X43: 0.02 | Y43: 0.02 | Z43: 0.02 | AA43: 0.02 | AB43: 0.02 | BL43: =ROUND($BL27*E43,0) -> 10 | BM43: =ROUND($BL27*F43,0) -> 10 | BN43: =ROUND($BL27*G43,0) -> 10 | BO43: =ROUND($BL27*H43,0) -> 10 | BP43: =ROUND($BL27*I43,0) -> 10 | BQ43: =ROUND($BL27*J43,0) -> 10 | BR43: =ROUND($BL27*K43,0) -> 10 | BS43: =ROUND($BL27*L43,0) -> 10 | ... DJ43: =ROUND($BL27*BC43,0) -> 0
B44: Week | C44: 2 | D44: 1 – 19 | E44: 0.02 | F44: 0.02 | G44: 0.02 | H44: 0.02 | I44: 0.08 | J44: 0.08 | K44: 0.07 | L44: 0.07 | M44: 0.06 | N44: 0.06 | O44: 0.05 | P44: 0.05 | Q44: 0.05 | R44: 0.04 | S44: 0.04 | T44: 0.04 | U44: 0.04 | V44: 0.03 | W44: 0.03 | X44: 0.03 | Y44: 0.03 | Z44: 0.03 | AA44: 0.02 | AB44: 0.02 | BL44: =ROUND($BL28*E44,0) -> 0 | BM44: =ROUND($BL28*F44,0) -> 0 | BN44: =ROUND($BL28*G44,0) -> 0 | BO44: =ROUND($BL28*H44,0) -> 0 | BP44: =ROUND($BL28*I44,0) -> 1 | BQ44: =ROUND($BL28*J44,0) -> 1 | BR44: =ROUND($BL28*K44,0) -> 1 | BS44: =ROUND($BL28*L44,0) -> 1 | ... DJ44: =ROUND($BL28*BC44,0) -> 0
B45: Week | C45: 2 | D45: 20 – 29 | H45: 0.08 | I45: 0.08 | J45: 0.07 | K45: 0.07 | L45: 0.06 | M45: 0.06 | N45: 0.05 | O45: 0.05 | P45: 0.05 | Q45: 0.04 | R45: 0.04 | S45: 0.04 | T45: 0.04 | U45: 0.03 | V45: 0.03 | W45: 0.03 | X45: 0.03 | Y45: 0.03 | Z45: 0.02 | AA45: 0.02 | AB45: 0.03 | AC45: 0.03 | AD45: 0.02 | BL45: =ROUND($BL29*E45,0) -> 0 | BM45: =ROUND($BL29*F45,0) -> 0 | BN45: =ROUND($BL29*G45,0) -> 0 | BO45: =ROUND($BL29*H45,0) -> 2 | BP45: =ROUND($BL29*I45,0) -> 2 | BQ45: =ROUND($BL29*J45,0) -> 2 | BR45: =ROUND($BL29*K45,0) -> 2 | BS45: =ROUND($BL29*L45,0) -> 2 | ... DJ45: =ROUND($BL29*BC45,0) -> 0
B46: Week | C46: 2 | D46: 30 – 39 | J46: 0.08 | K46: 0.08 | L46: 0.07 | M46: 0.07 | N46: 0.06 | O46: 0.06 | P46: 0.05 | Q46: 0.05 | R46: 0.05 | S46: 0.04 | T46: 0.04 | U46: 0.04 | V46: 0.04 | W46: 0.03 | X46: 0.03 | Y46: 0.03 | Z46: 0.03 | AA46: 0.03 | AB46: 0.02 | AC46: 0.02 | AD46: 0.03 | BL46: =ROUND($BL30*E46,0) -> 0 | BM46: =ROUND($BL30*F46,0) -> 0 | BN46: =ROUND($BL30*G46,0) -> 0 | BO46: =ROUND($BL30*H46,0) -> 0 | BP46: =ROUND($BL30*I46,0) -> 0 | BQ46: =ROUND($BL30*J46,0) -> 0 | BR46: =ROUND($BL30*K46,0) -> 0 | BS46: =ROUND($BL30*L46,0) -> 0 | ... DJ46: =ROUND($BL30*BC46,0) -> 0
B47: Week | C47: 2 | D47: 40 – 49 | K47: 0.08 | L47: 0.08 | M47: 0.07 | N47: 0.07 | O47: 0.06 | P47: 0.06 | Q47: 0.05 | R47: 0.05 | S47: 0.05 | T47: 0.04 | U47: 0.04 | V47: 0.04 | W47: 0.04 | X47: 0.03 | Y47: 0.03 | Z47: 0.03 | AA47: 0.03 | AB47: 0.03 | AC47: 0.02 | AD47: 0.02 | BL47: =ROUND($BL31*E47,0) -> 0 | BM47: =ROUND($BL31*F47,0) -> 0 | BN47: =ROUND($BL31*G47,0) -> 0 | BO47: =ROUND($BL31*H47,0) -> 0 | BP47: =ROUND($BL31*I47,0) -> 0 | BQ47: =ROUND($BL31*J47,0) -> 0 | BR47: =ROUND($BL31*K47,0) -> 0 | BS47: =ROUND($BL31*L47,0) -> 0 | ... DJ47: =ROUND($BL31*BC47,0) -> 0
...
